Workbook

Sheet store_performance
A1: store_id | B1: month | C1: region | D1: store_type | E1: marketing_spend | F1: footfall | G1: avg_discount_pct | H1: staff_count | I1: inventory_availability_pct | J1: competitor_distance_km | K1: holiday_flag | L1: customer_rating | M1: monthly_sales | N1: monthly_profit
A2: STR-1001 | B2: 45658 | C2: East | D2: Residential | E2: 70389.11 | F2: 8302 | G2: 0.042 | H2: 17 | I2: 75 | J2: 5.28 | K2: 1 | L2: 3.1 | M2: 658832.62 | N2: 84349.93
A3: STR-1001 | B3: 45689 | C3: East | D3: Residential | E3: 43827.89 | F3: 8487 | G3: 0.168 | H3: 23 | I3: 84.4 | J3: 4.31 | K3: 0 | L3: 2.8 | M3: 634436 | N3: 106130.54
A4: STR-1001 | B4: 45717 | C4: East | D4: Residential | E4: 59921.75 | F4: 9113 | G4: 0.133 | H4: 20 | I4: 88 | J4: 12 | K4: 0 | L4: 3.2 | M4: 678722.06 | N4: 101883.86
A5: STR-1001 | B5: 45748 | C5: East | D5: Residential | E5: 56856.63 | F5: 9431 | G5: 0.142 | H5: 23 | I5: 86.9 | J5: 4.97 | K5: 0 | L5: 3.4 | M5: 658920.3 | N5: 97910.37
A6: STR-1002 | B6: 45658 | C6: East | D6: High Street | E6: 48412.64 | F6: 9545 | G6: 0.231 | H6: 21 | I6: 97.6 | J6: 6.94 | K6: 1 | L6: 4.2 | M6: 741341.44 | N6: 119208.17
A7: STR-1002 | B7: 45689 | C7: East | D7: High Street | E7: 64811.21 | F7: 9792 | G7: 0.112 | H7: 20 | I7: 84.2 | J7: 2.88 | K7: 0 | L7: 4.2 | M7: 761835.34 | N7: 149602.23
A8: STR-1002 | B8: 45717 | C8: East | D8: High Street | E8: 46213.45 | F8: 10616 | G8: 0.122 | H8: 22 | I8: 85.2 | J8: 0.2 | K8: 1 | L8: 4.1 | M8: 806615.54 | N8: 131364.62
A9: STR-1002 | B9: 45748 | C9: East | D9: High Street | E9: 68148.52 | F9: 8567 | G9: 0.127 | H9: 23 | I9: 95.6 | J9: 0.8 | K9: 0 | L9: 3.9 | M9: 850164.26 | N9: 149262.75
A10: STR-1003 | B10: 45658 | C10: North | D10: Airport | E10: 71838.86 | F10: 10979 | G10: 0.215 | H10: 26 | I10: 88.6 | J10: 7.7 | K10: 1 | L10: 3.8 | M10: 930581.7 | N10: 136207.98
A11: STR-1003 | B11: 45689 | C11: North | D11: Airport | E11: 68133.44 | F11: 9459 | G11: 0.22 | H11: 21 | I11: 85 | J11: 1.91 | K11: 0 | L11: 4.2 | M11: 779010.94 | N11: 106328.09
A12: STR-1003 | B12: 45717 | C12: North | D12: Airport | E12: 34285.21 | F12: 9172 | G12: 0.213 | H12: 22 | I12: 88.3 | J12: 10.46 | K12: 1 | L12: 3.8 | M12: 723060.76 | N12: 123131.24
A13: STR-1003 | B13: 45748 | C13: North | D13: Airport | E13: 67979.88 | F13: 11230 | G13: 0.002 | H13: 28 | I13: 85.3 | J13: 7.16 | K13: 0 | L13: 3.8 | M13: 910791.94 | N13: 158891.28
... A34: STR-1009 | B34: 45658 | C34: North | D34: Residential | E34: 54597.83 | F34: 9429 | G34: 0.188 | H34: 21 | I34: 83.3 | J34: 11.71 | K34: 0 | L34: 4.2 | M34: 641865.03 | N34: 81342.58
A35: STR-1009 | B35: 45689 | C35: North | D35: Residential | E35: 73771.91 | F35: 11695 | G35: 0.07 | H35: 25 | I35: 84.7 | J35: 0.62 | K35: 0 | M35: 799477.76 | N35: 164974.41
A36: STR-1009 | B36: 45717 | C36: North | D36: Residential | E36: 74413.88 | F36: 9449 | G36: 0.039 | H36: 23 | I36: 92.1 | J36: 2.12 | K36: 0 | L36: 3.5 | M36: 798952.17 | N36: 161499.04
A37: STR-1009 | B37: 45748 | C37: North | D37: Residential | E37: 52483.77 | F37: 10453 | G37: 0.247 | H37: 25 | I37: 99 | J37: 6.31 | K37: 0 | L37: 3.6 | M37: 800979.78 | N37: 149242.27
A38: STR-1010 | B38: 45658 | C38: North | D38: Mall | E38: 75269.87 | F38: 8838 | G38: 0.092 | H38: 21 | I38: 83.1 | J38: 9.56 | K38: 1 | L38: 4.2 | M38: 820593.93 | N38: 115860.06
A39: STR-1010 | B39: 45689 | C39: North | D39: Mall | E39: 61245.41 | F39: 8156 | G39: 0.156 | H39: 19 | I39: 92.9 | J39: 9.05 | K39: 0 | L39: 3.8 | M39: 718330.53 | N39: 93247.9
A40: STR-1010 | B40: 45717 | C40: North | D40: Mall | E40: 93381.26 | F40: 7562 | G40: 0.198 | H40: 19 | I40: 82.9 | J40: 5.05 | K40: 0 | L40: 4 | M40: 736633.4 | N40: 115654.66
A41: STR-1010 | B41: 45748 | C41: North | D41: Mall | E41: 65012.19 | F41: 9598 | G41: 0.085 | H41: 24 | I41: 98.3 | J41: 0.89 | K41: 0 | L41: 3.8 | M41: 828623.85 | N41: 167320.52
A42: STR-1011 | B42: 45658 | C42: East | D42: Mall | E42: 40462.94 | F42: 3660 | G42: 0.218 | H42: 11 | I42: 95.2 | J42: 5.57 | K42: 0 | L42: 4.4 | M42: 592195.85 | N42: 92291.56
A43: STR-1011 | B43: 45689 | C43: East | D43: Mall | E43: 46123.88 | F43: 3227 | G43: 0.143 | H43: 10 | I43: 75.4 | J43: 1.06 | K43: 0 | L43: 4.4 | M43: 532644.46 | N43: 60681.32
A44: STR-1011 | B44: 45717 | C44: East | D44: Mall | E44: 68077.54 | F44: 3360 | G44: 0.128 | H44: 14 | I44: 88.2 | J44: 1.24 | K44: 1 | L44: 4 | M44: 657429.18 | N44: 88919.74
A45: STR-1011 | B45: 45748 | C45: East | D45: Mall | E45: 64882.14 | F45: 3642 | G45: 0.019 | H45: 13 | I45: 87.8 | J45: 4.52 | K45: 0 | L45: 4.2 | M45: 605178 | N45: 106958.74
A46: STR-1012 | B46: 45658 | C46: West | D46: Residential | E46: 138855.51 | F46: 5145 | G46: 0.06 | H46: 17 | I46: 88.2 | J46: 9.58 | K46: 0 | L46: 3.2 | M46: 595467.6 | N46: 104276.46
A47: STR-1012 | B47: 45689 | C47: West | D47: Residential | E47: 63630.21 | F47: 4460 | G47: 0.235 | H47: 14 | I47: 98.6 | J47: 5.52 | K47: 0 | L47: 3.5 | M47: 599603.4 | N47: 112685.12
... A72: STR-1018 | B72: 45717 | C72: East | D72: High Street | E72: 60571.82 | F72: 3193 | G72: 0.197 | H72: 7 | I72: 99 | J72: 1.43 | K72: 0 | L72: 3.2 | M72: 605023.87 | N72: 98545.81
A73: STR-1018 | B73: 45748 | C73: East | D73: High Street | E73: 55081.16 | F73: 5485 | G73: 0.036 | H73: 12 | I73: 88 | K73: 0 | L73: 3.5 | M73: 674774.09 | N73: 141917.59
A74: STR-1019 | B74: 45658 | C74: East | D74: Residential | E74: 46201.46 | F74: 5918 | G74: 0.277 | H74: 13 | I74: 78.8 | J74: 4.91 | K74: 0 | L74: 4.5 | M74: 616069.41 | N74: 54453.99
A75: STR-1019 | B75: 45689 | C75: East | D75: Residential | E75: 53762.92 | F75: 6821 | G75: 0.066 | H75: 19 | I75: 94.6 | J75: 7.03 | K75: 0 | L75: 4.4 | M75: 630829.94 | N75: 117090.02
A76: STR-1019 | B76: 45717 | C76: East | D76: Residential | E76: 70144.78 | F76: 6806 | G76: 0.178 | H76: 20 | I76: 93.1 | J76: 0.28 | K76: 1 | L76: 4.3 | M76: 788087.68 | N76: 116803.42
A77: STR-1019 | B77: 45748 | C77: East | D77: Residential | E77: 58749.63 | F77: 8252 | G77: 0.203 | H77: 20 | I77: 85.2 | J77: 3.61 | K77: 0 | L77: 4.5 | M77: 680840.36 | N77: 68007.68
A78: STR-1020 | B78: 45658 | C78: South | D78: High Street | E78: 56973.18 | F78: 6662 | G78: 0.1 | H78: 15 | I78: 77.7 | J78: 7.52 | K78: 1 | L78: 3.2 | M78: 643657.47 | N78: 87022.45
A79: STR-1020 | B79: 45689 | C79: South | D79: High Street | E79: 54872.82 | F79: 5962 | G79: 0.064 | H79: 12 | I79: 85.4 | J79: 2.58 | K79: 0 | L79: 2.9 | M79: 691112.6 | N79: 109212.83
A80: STR-1020 | B80: 45717 | C80: South | D80: High Street | E80: 80562.81 | F80: 7470 | G80: 0.172 | H80: 16 | I80: 83.5 | J80: 2.29 | K80: 0 | L80: 3.3 | M80: 776922.17 | N80: 150701.93
A81: STR-1020 | B81: 45748 | C81: South | D81: High Street | E81: 77999.9 | F81: 5974 | G81: 0.252 | H81: 14 | I81: 81.3 | J81: 2.39 | K81: 0 | L81: 3.2 | M81: 636561.34 | N81: 93861.06
A82: STR-1021 | B82: 45658 | C82: West | D82: Mall | E82: 60881.01 | F82: 5410 | G82: 0.179 | H82: 15 | I82: 83.9 | J82: 5.24 | K82: 0 | L82: 4.6 | M82: 621369.58 | N82: 85493.64
A83: STR-1021 | B83: 45689 | C83: West | D83: Mall | E83: 60628.38 | F83: 4451 | G83: 0.095 | H83: 10 | I83: 89.6 | J83: 3.17 | K83: 0 | L83: 4.6 | M83: 682208.01 | N83: 110318.84
A84: STR-1021 | B84: 45717 | C84: West | D84: Mall | E84: 72731.14 | F84: 4644 | G84: 0.084 | H84: 15 | I84: 87.1 | J84: 2.66 | K84: 0 | L84: 4.6 | M84: 727241.86 | N84: 155810.3
...

Sheet cleaned_data_dummy
A3: Row Labels
A4: East
A5: North
A6: South
A7: West
A8: Grand Total
A10: Row Labels
A11: Airport
A12: High Street
A13: Mall
A14: Residential
A15: Grand Total

Sheet cleaned_data
A1: store_id | B1: month | C1: region | D1: store_type | E1: marketing_spend | F1: footfall | G1: avg_discount_pct | H1: staff_count | I1: inventory_availability_pct | J1: competitor_distance_km | K1: holiday_flag | L1: customer_rating | M1: monthly_sales | N1: monthly_profit
A2: STR-1001 | B2: 45658 | C2: East | D2: Residential | E2: 70389.11 | F2: 8302 | G2: 0.042 | H2: 17 | I2: 75 | J2: 5.28 | K2: 1 | L2: 3.1 | M2: 658832.62 | N2: 84349.93
A3: STR-1001 | B3: 45689 | C3: East | D3: Residential | E3: 43827.89 | F3: 8487 | G3: 0.168 | H3: 23 | I3: 84.4 | J3: 4.31 | K3: 0 | L3: 2.8 | M3: 634436 | N3: 106130.54
A4: STR-1001 | B4: 45717 | C4: East | D4: Residential | E4: 59921.75 | F4: 9113 | G4: 0.133 | H4: 20 | I4: 88 | J4: 12 | K4: 0 | L4: 3.2 | M4: 678722.06 | N4: 101883.86
A5: STR-1001 | B5: 45748 | C5: East | D5: Residential | E5: 56856.63 | F5: 9431 | G5: 0.142 | H5: 23 | I5: 86.9 | J5: 4.97 | K5: 0 | L5: 3.4 | M5: 658920.3 | N5: 97910.37
A6: STR-1002 | B6: 45658 | C6: East | D6: High Street | E6: 48412.64 | F6: 9545 | G6: 0.231 | H6: 21 | I6: 97.6 | J6: 6.94 | K6: 1 | L6: 4.2 | M6: 741341.44 | N6: 119208.17
A7: STR-1002 | B7: 45689 | C7: East | D7: High Street | E7: 64811.21 | F7: 9792 | G7: 0.112 | H7: 20 | I7: 84.2 | J7: 2.88 | K7: 0 | L7: 4.2 | M7: 761835.34 | N7: 149602.23
A8: STR-1002 | B8: 45717 | C8: East | D8: High Street | E8: 46213.45 | F8: 10616 | G8: 0.122 | H8: 22 | I8: 85.2 | J8: 0.2 | K8: 1 | L8: 4.1 | M8: 806615.54 | N8: 131364.62
A9: STR-1002 | B9: 45748 | C9: East | D9: High Street | E9: 68148.52 | F9: 8567 | G9: 0.127 | H9: 23 | I9: 95.6 | J9: 0.8 | K9: 0 | L9: 3.9 | M9: 850164.26 | N9: 149262.75
A10: STR-1003 | B10: 45658 | C10: North | D10: Airport | E10: 71838.86 | F10: 10979 | G10: 0.215 | H10: 26 | I10: 88.6 | J10: 7.7 | K10: 1 | L10: 3.8 | M10: 930581.7 | N10: 136207.98
A11: STR-1003 | B11: 45689 | C11: North | D11: Airport | E11: 68133.44 | F11: 9459 | G11: 0.22 | H11: 21 | I11: 85 | J11: 1.91 | K11: 0 | L11: 4.2 | M11: 779010.94 | N11: 106328.09
A12: STR-1003 | B12: 45717 | C12: North | D12: Airport | E12: 34285.21 | F12: 9172 | G12: 0.213 | H12: 22 | I12: 88.3 | J12: 10.46 | K12: 1 | L12: 3.8 | M12: 723060.76 | N12: 123131.24
A13: STR-1003 | B13: 45748 | C13: North | D13: Airport | E13: 67979.88 | F13: 11230 | G13: 0.002 | H13: 28 | I13: 85.3 | J13: 7.16 | K13: 0 | L13: 3.8 | M13: 910791.94 | N13: 158891.28
... A34: STR-1009 | B34: 45658 | C34: North | D34: Residential | E34: 54597.83 | F34: 9429 | G34: 0.188 | H34: 21 | I34: 83.3 | J34: 11.71 | K34: 0 | L34: 4.2 | M34: 641865.03 | N34: 81342.58
A35: STR-1009 | B35: 45689 | C35: North | D35: Residential | E35: 73771.91 | F35: 11695 | G35: 0.07 | H35: 25 | I35: 84.7 | J35: 0.62 | K35: 0 | M35: 799477.76 | N35: 164974.41
A36: STR-1009 | B36: 45717 | C36: North | D36: Residential | E36: 74413.88 | F36: 9449 | G36: 0.039 | H36: 23 | I36: 92.1 | J36: 2.12 | K36: 0 | L36: 3.5 | M36: 798952.17 | N36: 161499.04
A37: STR-1009 | B37: 45748 | C37: North | D37: Residential | E37: 52483.77 | F37: 10453 | G37: 0.247 | H37: 25 | I37: 99 | J37: 6.31 | K37: 0 | L37: 3.6 | M37: 800979.78 | N37: 149242.27
A38: STR-1010 | B38: 45658 | C38: North | D38: Mall | E38: 75269.87 | F38: 8838 | G38: 0.092 | H38: 21 | I38: 83.1 | J38: 9.56 | K38: 1 | L38: 4.2 | M38: 820593.93 | N38: 115860.06
A39: STR-1010 | B39: 45689 | C39: North | D39: Mall | E39: 61245.41 | F39: 8156 | G39: 0.156 | H39: 19 | I39: 92.9 | J39: 9.05 | K39: 0 | L39: 3.8 | M39: 718330.53 | N39: 93247.9
A40: STR-1010 | B40: 45717 | C40: North | D40: Mall | E40: 93381.26 | F40: 7562 | G40: 0.198 | H40: 19 | I40: 82.9 | J40: 5.05 | K40: 0 | L40: 4 | M40: 736633.4 | N40: 115654.66
A41: STR-1010 | B41: 45748 | C41: North | D41: Mall | E41: 65012.19 | F41: 9598 | G41: 0.085 | H41: 24 | I41: 98.3 | J41: 0.89 | K41: 0 | L41: 3.8 | M41: 828623.85 | N41: 167320.52
A42: STR-1011 | B42: 45658 | C42: East | D42: Mall | E42: 40462.94 | F42: 3660 | G42: 0.218 | H42: 11 | I42: 95.2 | J42: 5.57 | K42: 0 | L42: 4.4 | M42: 592195.85 | N42: 92291.56
A43: STR-1011 | B43: 45689 | C43: East | D43: Mall | E43: 46123.88 | F43: 3227 | G43: 0.143 | H43: 10 | I43: 75.4 | J43: 1.06 | K43: 0 | L43: 4.4 | M43: 532644.46 | N43: 60681.32
A44: STR-1011 | B44: 45717 | C44: East | D44: Mall | E44: 68077.54 | F44: 3360 | G44: 0.128 | H44: 14 | I44: 88.2 | J44: 1.24 | K44: 1 | L44: 4 | M44: 657429.18 | N44: 88919.74
A45: STR-1011 | B45: 45748 | C45: East | D45: Mall | E45: 64882.14 | F45: 3642 | G45: 0.019 | H45: 13 | I45: 87.8 | J45: 4.52 | K45: 0 | L45: 4.2 | M45: 605178 | N45: 106958.74
A46: STR-1012 | B46: 45658 | C46: West | D46: Residential | E46: 138855.51 | F46: 5145 | G46: 0.06 | H46: 17 | I46: 88.2 | J46: 9.58 | K46: 0 | L46: 3.2 | M46: 595467.6 | N46: 104276.46
A47: STR-1012 | B47: 45689 | C47: West | D47: Residential | E47: 63630.21 | F47: 4460 | G47: 0.235 | H47: 14 | I47: 98.6 | J47: 5.52 | K47: 0 | L47: 3.5 | M47: 599603.4 | N47: 112685.12
... A72: STR-1018 | B72: 45717 | C72: East | D72: High Street | E72: 60571.82 | F72: 3193 | G72: 0.197 | H72: 7 | I72: 99 | J72: 1.43 | K72: 0 | L72: 3.2 | M72: 605023.87 | N72: 98545.81
A73: STR-1018 | B73: 45748 | C73: East | D73: High Street | E73: 55081.16 | F73: 5485 | G73: 0.036 | H73: 12 | I73: 88 | K73: 0 | L73: 3.5 | M73: 674774.09 | N73: 141917.59
A74: STR-1019 | B74: 45658 | C74: East | D74: Residential | E74: 46201.46 | F74: 5918 | G74: 0.277 | H74: 13 | I74: 78.8 | J74: 4.91 | K74: 0 | L74: 4.5 | M74: 616069.41 | N74: 54453.99
A75: STR-1019 | B75: 45689 | C75: East | D75: Residential | E75: 53762.92 | F75: 6821 | G75: 0.066 | H75: 19 | I75: 94.6 | J75: 7.03 | K75: 0 | L75: 4.4 | M75: 630829.94 | N75: 117090.02
A76: STR-1019 | B76: 45717 | C76: East | D76: Residential | E76: 70144.78 | F76: 6806 | G76: 0.178 | H76: 20 | I76: 93.1 | J76: 0.28 | K76: 1 | L76: 4.3 | M76: 788087.68 | N76: 116803.42
A77: STR-1019 | B77: 45748 | C77: East | D77: Residential | E77: 58749.63 | F77: 8252 | G77: 0.203 | H77: 20 | I77: 85.2 | J77: 3.61 | K77: 0 | L77: 4.5 | M77: 680840.36 | N77: 68007.68
A78: STR-1020 | B78: 45658 | C78: South | D78: High Street | E78: 56973.18 | F78: 6662 | G78: 0.1 | H78: 15 | I78: 77.7 | J78: 7.52 | K78: 1 | L78: 3.2 | M78: 643657.47 | N78: 87022.45
A79: STR-1020 | B79: 45689 | C79: South | D79: High Street | E79: 54872.82 | F79: 5962 | G79: 0.064 | H79: 12 | I79: 85.4 | J79: 2.58 | K79: 0 | L79: 2.9 | M79: 691112.6 | N79: 109212.83
A80: STR-1020 | B80: 45717 | C80: South | D80: High Street | E80: 80562.81 | F80: 7470 | G80: 0.172 | H80: 16 | I80: 83.5 | J80: 2.29 | K80: 0 | L80: 3.3 | M80: 776922.17 | N80: 150701.93
A81: STR-1020 | B81: 45748 | C81: South | D81: High Street | E81: 77999.9 | F81: 5974 | G81: 0.252 | H81: 14 | I81: 81.3 | J81: 2.39 | K81: 0 | L81: 3.2 | M81: 636561.34 | N81: 93861.06
A82: STR-1021 | B82: 45658 | C82: West | D82: Mall | E82: 60881.01 | F82: 5410 | G82: 0.179 | H82: 15 | I82: 83.9 | J82: 5.24 | K82: 0 | L82: 4.6 | M82: 621369.58 | N82: 85493.64
A83: STR-1021 | B83: 45689 | C83: West | D83: Mall | E83: 60628.38 | F83: 4451 | G83: 0.095 | H83: 10 | I83: 89.6 | J83: 3.17 | K83: 0 | L83: 4.6 | M83: 682208.01 | N83: 110318.84
A84: STR-1021 | B84: 45717 | C84: West | D84: Mall | E84: 72731.14 | F84: 4644 | G84: 0.084 | H84: 15 | I84: 87.1 | J84: 2.66 | K84: 0 | L84: 4.6 | M84: 727241.86 | N84: 155810.3
...

Sheet Dummy_Variables
A1: store_id | B1: month | C1: region | D1: store_type | E1: marketing_spend | F1: footfall | G1: avg_discount_pct | H1: inventory_availability_pct | I1: Region_North | J1: staff_count | K1: inventory_availability_pct | L1: competitor_distance_km | M1: holiday_flag | N1: customer_rating | O1: monthly_sales | P1: monthly_profit | Q1: Region_East | R1: Region_South | S1: Store_Airport | T1: Store_HighStreet | U1: Store_Mall
A2: STR-1001 | B2: 45658 | C2: East | D2: Residential | E2: 70389.11 | F2: 8302 | G2: 0.042 | H2: 75 | I2: =IF(C2="North",1,0) -> 0 | J2: 17 | K2: 75 | L2: 5.28 | M2: 1 | N2: 3.1 | O2: 658832.62 | P2: 84349.93 | Q2: =IF(C2="East",1,0) -> 1 | R2: =IF(C2="South",1,0) -> 0 | S2: =IF(D2="Airport",1,0) -> 0 | T2: =IF(D2="High Street",1,0) -> 0 | U2: =IF(D2="Mall",1,0) -> 0
A3: STR-1001 | B3: 45689 | C3: East | D3: Residential | E3: 43827.89 | F3: 8487 | G3: 0.168 | H3: 84.4 | I3: =IF(C3="North",1,0) -> 0 | J3: 23 | K3: 84.4 | L3: 4.31 | M3: 0 | N3: 2.8 | O3: 634436 | P3: 106130.54 | Q3: =IF(C3="East",1,0) -> 1 | R3: =IF(C3="South",1,0) -> 0 | S3: =IF(D3="Airport",1,0) -> 0 | T3: =IF(D3="High Street",1,0) -> 0 | U3: =IF(D3="Mall",1,0) -> 0
A4: STR-1001 | B4: 45717 | C4: East | D4: Residential | E4: 59921.75 | F4: 9113 | G4: 0.133 | H4: 88 | I4: =IF(C4="North",1,0) -> 0 | J4: 20 | K4: 88 | L4: 12 | M4: 0 | N4: 3.2 | O4: 678722.06 | P4: 101883.86 | Q4: =IF(C4="East",1,0) -> 1 | R4: =IF(C4="South",1,0) -> 0 | S4: =IF(D4="Airport",1,0) -> 0 | T4: =IF(D4="High Street",1,0) -> 0 | U4: =IF(D4="Mall",1,0) -> 0
A5: STR-1001 | B5: 45748 | C5: East | D5: Residential | E5: 56856.63 | F5: 9431 | G5: 0.142 | H5: 86.9 | I5: =IF(C5="North",1,0) -> 0 | J5: 23 | K5: 86.9 | L5: 4.97 | M5: 0 | N5: 3.4 | O5: 658920.3 | P5: 97910.37 | Q5: =IF(C5="East",1,0) -> 1 | R5: =IF(C5="South",1,0) -> 0 | S5: =IF(D5="Airport",1,0) -> 0 | T5: =IF(D5="High Street",1,0) -> 0 | U5: =IF(D5="Mall",1,0) -> 0
A6: STR-1002 | B6: 45658 | C6: East | D6: High Street | E6: 48412.64 | F6: 9545 | G6: 0.231 | H6: 97.6 | I6: =IF(C6="North",1,0) -> 0 | J6: 21 | K6: 97.6 | L6: 6.94 | M6: 1 | N6: 4.2 | O6: 741341.44 | P6: 119208.17 | Q6: =IF(C6="East",1,0) -> 1 | R6: =IF(C6="South",1,0) -> 0 | S6: =IF(D6="Airport",1,0) -> 0 | T6: =IF(D6="High Street",1,0) -> 1 | U6: =IF(D6="Mall",1,0) -> 0
A7: STR-1002 | B7: 45689 | C7: East | D7: High Street | E7: 64811.21 | F7: 9792 | G7: 0.112 | H7: 84.2 | I7: =IF(C7="North",1,0) -> 0 | J7: 20 | K7: 84.2 | L7: 2.88 | M7: 0 | N7: 4.2 | O7: 761835.34 | P7: 149602.23 | Q7: =IF(C7="East",1,0) -> 1 | R7: =IF(C7="South",1,0) -> 0 | S7: =IF(D7="Airport",1,0) -> 0 | T7: =IF(D7="High Street",1,0) -> 1 | U7: =IF(D7="Mall",1,0) -> 0
A8: STR-1002 | B8: 45717 | C8: East | D8: High Street | E8: 46213.45 | F8: 10616 | G8: 0.122 | H8: 85.2 | I8: =IF(C8="North",1,0) -> 0 | J8: 22 | K8: 85.2 | L8: 0.2 | M8: 1 | N8: 4.1 | O8: 806615.54 | P8: 131364.62 | Q8: =IF(C8="East",1,0) -> 1 | R8: =IF(C8="South",1,0) -> 0 | S8: =IF(D8="Airport",1,0) -> 0 | T8: =IF(D8="High Street",1,0) -> 1 | U8: =IF(D8="Mall",1,0) -> 0
A9: STR-1002 | B9: 45748 | C9: East | D9: High Street | E9: 68148.52 | F9: 8567 | G9: 0.127 | H9: 95.6 | I9: =IF(C9="North",1,0) -> 0 | J9: 23 | K9: 95.6 | L9: 0.8 | M9: 0 | N9: 3.9 | O9: 850164.26 | P9: 149262.75 | Q9: =IF(C9="East",1,0) -> 1 | R9: =IF(C9="South",1,0) -> 0 | S9: =IF(D9="Airport",1,0) -> 0 | T9: =IF(D9="High Street",1,0) -> 1 | U9: =IF(D9="Mall",1,0) -> 0
A10: STR-1003 | B10: 45658 | C10: North | D10: Airport | E10: 71838.86 | F10: 10979 | G10: 0.215 | H10: 88.6 | I10: =IF(C10="North",1,0) -> 1 | J10: 26 | K10: 88.6 | L10: 7.7 | M10: 1 | N10: 3.8 | O10: 930581.7 | P10: 136207.98 | Q10: =IF(C10="East",1,0) -> 0 | R10: =IF(C10="South",1,0) -> 0 | S10: =IF(D10="Airport",1,0) -> 1 | T10: =IF(D10="High Street",1,0) -> 0 | U10: =IF(D10="Mall",1,0) -> 0
A11: STR-1003 | B11: 45689 | C11: North | D11: Airport | E11: 68133.44 | F11: 9459 | G11: 0.22 | H11: 85 | I11: =IF(C11="North",1,0) -> 1 | J11: 21 | K11: 85 | L11: 1.91 | M11: 0 | N11: 4.2 | O11: 779010.94 | P11: 106328.09 | Q11: =IF(C11="East",1,0) -> 0 | R11: =IF(C11="South",1,0) -> 0 | S11: =IF(D11="Airport",1,0) -> 1 | T11: =IF(D11="High Street",1,0) -> 0 | U11: =IF(D11="Mall",1,0) -> 0
A12: STR-1003 | B12: 45717 | C12: North | D12: Airport | E12: 34285.21 | F12: 9172 | G12: 0.213 | H12: 88.3 | I12: =IF(C12="North",1,0) -> 1 | J12: 22 | K12: 88.3 | L12: 10.46 | M12: 1 | N12: 3.8 | O12: 723060.76 | P12: 123131.24 | Q12: =IF(C12="East",1,0) -> 0 | R12: =IF(C12="South",1,0) -> 0 | S12: =IF(D12="Airport",1,0) -> 1 | T12: =IF(D12="High Street",1,0) -> 0 | U12: =IF(D12="Mall",1,0) -> 0
A13: STR-1003 | B13: 45748 | C13: North | D13: Airport | E13: 67979.88 | F13: 11230 | G13: 0.002 | H13: 85.3 | I13: =IF(C13="North",1,0) -> 1 | J13: 28 | K13: 85.3 | L13: 7.16 | M13: 0 | N13: 3.8 | O13: 910791.94 | P13: 158891.28 | Q13: =IF(C13="East",1,0) -> 0 | R13: =IF(C13="South",1,0) -> 0 | S13: =IF(D13="Airport",1,0) -> 1 | T13: =IF(D13="High Street",1,0) -> 0 | U13: =IF(D13="Mall",1,0) -> 0
... A34: STR-1009 | B34: 45658 | C34: North | D34: Residential | E34: 54597.83 | F34: 9429 | G34: 0.188 | H34: 83.3 | I34: =IF(C34="North",1,0) -> 1 | J34: 21 | K34: 83.3 | L34: 11.71 | M34: 0 | N34: 4.2 | O34: 641865.03 | P34: 81342.58 | Q34: =IF(C34="East",1,0) -> 0 | R34: =IF(C34="South",1,0) -> 0 | S34: =IF(D34="Airport",1,0) -> 0 | T34: =IF(D34="High Street",1,0) -> 0 | U34: =IF(D34="Mall",1,0) -> 0
A35: STR-1009 | B35: 45689 | C35: North | D35: Residential | E35: 73771.91 | F35: 11695 | G35: 0.07 | H35: 84.7 | I35: =IF(C35="North",1,0) -> 1 | J35: 25 | K35: 84.7 | L35: 0.62 | M35: 0 | O35: 799477.76 | P35: 164974.41 | Q35: =IF(C35="East",1,0) -> 0 | R35: =IF(C35="South",1,0) -> 0 | S35: =IF(D35="Airport",1,0) -> 0 | T35: =IF(D35="High Street",1,0) -> 0 | U35: =IF(D35="Mall",1,0) -> 0
A36: STR-1009 | B36: 45717 | C36: North | D36: Residential | E36: 74413.88 | F36: 9449 | G36: 0.039 | H36: 92.1 | I36: =IF(C36="North",1,0) -> 1 | J36: 23 | K36: 92.1 | L36: 2.12 | M36: 0 | N36: 3.5 | O36: 798952.17 | P36: 161499.04 | Q36: =IF(C36="East",1,0) -> 0 | R36: =IF(C36="South",1,0) -> 0 | S36: =IF(D36="Airport",1,0) -> 0 | T36: =IF(D36="High Street",1,0) -> 0 | U36: =IF(D36="Mall",1,0) -> 0
A37: STR-1009 | B37: 45748 | C37: North | D37: Residential | E37: 52483.77 | F37: 10453 | G37: 0.247 | H37: 99 | I37: =IF(C37="North",1,0) -> 1 | J37: 25 | K37: 99 | L37: 6.31 | M37: 0 | N37: 3.6 | O37: 800979.78 | P37: 149242.27 | Q37: =IF(C37="East",1,0) -> 0 | R37: =IF(C37="South",1,0) -> 0 | S37: =IF(D37="Airport",1,0) -> 0 | T37: =IF(D37="High Street",1,0) -> 0 | U37: =IF(D37="Mall",1,0) -> 0
A38: STR-1010 | B38: 45658 | C38: North | D38: Mall | E38: 75269.87 | F38: 8838 | G38: 0.092 | H38: 83.1 | I38: =IF(C38="North",1,0) -> 1 | J38: 21 | K38: 83.1 | L38: 9.56 | M38: 1 | N38: 4.2 | O38: 820593.93 | P38: 115860.06 | Q38: =IF(C38="East",1,0) -> 0 | R38: =IF(C38="South",1,0) -> 0 | S38: =IF(D38="Airport",1,0) -> 0 | T38: =IF(D38="High Street",1,0) -> 0 | U38: =IF(D38="Mall",1,0) -> 1
A39: STR-1010 | B39: 45689 | C39: North | D39: Mall | E39: 61245.41 | F39: 8156 | G39: 0.156 | H39: 92.9 | I39: =IF(C39="North",1,0) -> 1 | J39: 19 | K39: 92.9 | L39: 9.05 | M39: 0 | N39: 3.8 | O39: 718330.53 | P39: 93247.9 | Q39: =IF(C39="East",1,0) -> 0 | R39: =IF(C39="South",1,0) -> 0 | S39: =IF(D39="Airport",1,0) -> 0 | T39: =IF(D39="High Street",1,0) -> 0 | U39: =IF(D39="Mall",1,0) -> 1
A40: STR-1010 | B40: 45717 | C40: North | D40: Mall | E40: 93381.26 | F40: 7562 | G40: 0.198 | H40: 82.9 | I40: =IF(C40="North",1,0) -> 1 | J40: 19 | K40: 82.9 | L40: 5.05 | M40: 0 | N40: 4 | O40: 736633.4 | P40: 115654.66 | Q40: =IF(C40="East",1,0) -> 0 | R40: =IF(C40="South",1,0) -> 0 | S40: =IF(D40="Airport",1,0) -> 0 | T40: =IF(D40="High Street",1,0) -> 0 | U40: =IF(D40="Mall",1,0) -> 1
A41: STR-1010 | B41: 45748 | C41: North | D41: Mall | E41: 65012.19 | F41: 9598 | G41: 0.085 | H41: 98.3 | I41: =IF(C41="North",1,0) -> 1 | J41: 24 | K41: 98.3 | L41: 0.89 | M41: 0 | N41: 3.8 | O41: 828623.85 | P41: 167320.52 | Q41: =IF(C41="East",1,0) -> 0 | R41: =IF(C41="South",1,0) -> 0 | S41: =IF(D41="Airport",1,0) -> 0 | T41: =IF(D41="High Street",1,0) -> 0 | U41: =IF(D41="Mall",1,0) -> 1
A42: STR-1011 | B42: 45658 | C42: East | D42: Mall | E42: 40462.94 | F42: 3660 | G42: 0.218 | H42: 95.2 | I42: =IF(C42="North",1,0) -> 0 | J42: 11 | K42: 95.2 | L42: 5.57 | M42: 0 | N42: 4.4 | O42: 592195.85 | P42: 92291.56 | Q42: =IF(C42="East",1,0) -> 1 | R42: =IF(C42="South",1,0) -> 0 | S42: =IF(D42="Airport",1,0) -> 0 | T42: =IF(D42="High Street",1,0) -> 0 | U42: =IF(D42="Mall",1,0) -> 1
A43: STR-1011 | B43: 45689 | C43: East | D43: Mall | E43: 46123.88 | F43: 3227 | G43: 0.143 | H43: 75.4 | I43: =IF(C43="North",1,0) -> 0 | J43: 10 | K43: 75.4 | L43: 1.06 | M43: 0 | N43: 4.4 | O43: 532644.46 | P43: 60681.32 | Q43: =IF(C43="East",1,0) -> 1 | R43: =IF(C43="South",1,0) -> 0 | S43: =IF(D43="Airport",1,0) -> 0 | T43: =IF(D43="High Street",1,0) -> 0 | U43: =IF(D43="Mall",1,0) -> 1
A44: STR-1011 | B44: 45717 | C44: East | D44: Mall | E44: 68077.54 | F44: 3360 | G44: 0.128 | H44: 88.2 | I44: =IF(C44="North",1,0) -> 0 | J44: 14 | K44: 88.2 | L44: 1.24 | M44: 1 | N44: 4 | O44: 657429.18 | P44: 88919.74 | Q44: =IF(C44="East",1,0) -> 1 | R44: =IF(C44="South",1,0) -> 0 | S44: =IF(D44="Airport",1,0) -> 0 | T44: =IF(D44="High Street",1,0) -> 0 | U44: =IF(D44="Mall",1,0) -> 1
A45: STR-1011 | B45: 45748 | C45: East | D45: Mall | E45: 64882.14 | F45: 3642 | G45: 0.019 | H45: 87.8 | I45: =IF(C45="North",1,0) -> 0 | J45: 13 | K45: 87.8 | L45: 4.52 | M45: 0 | N45: 4.2 | O45: 605178 | P45: 106958.74 | Q45: =IF(C45="East",1,0) -> 1 | R45: =IF(C45="South",1,0) -> 0 | S45: =IF(D45="Airport",1,0) -> 0 | T45: =IF(D45="High Street",1,0) -> 0 | U45: =IF(D45="Mall",1,0) -> 1
A46: STR-1012 | B46: 45658 | C46: West | D46: Residential | E46: 138855.51 | F46: 5145 | G46: 0.06 | H46: 88.2 | I46: =IF(C46="North",1,0) -> 0 | J46: 17 | K46: 88.2 | L46: 9.58 | M46: 0 | N46: 3.2 | O46: 595467.6 | P46: 104276.46 | Q46: =IF(C46="East",1,0) -> 0 | R46: =IF(C46="South",1,0) -> 0 | S46: =IF(D46="Airport",1,0) -> 0 | T46: =IF(D46="High Street",1,0) -> 0 | U46: =IF(D46="Mall",1,0) -> 0
A47: STR-1012 | B47: 45689 | C47: West | D47: Residential | E47: 63630.21 | F47: 4460 | G47: 0.235 | H47: 98.6 | I47: =IF(C47="North",1,0) -> 0 | J47: 14 | K47: 98.6 | L47: 5.52 | M47: 0 | N47: 3.5 | O47: 599603.4 | P47: 112685.12 | Q47: =IF(C47="East",1,0) -> 0 | R47: =IF(C47="South",1,0) -> 0 | S47: =IF(D47="Airport",1,0) -> 0 | T47: =IF(D47="High Street",1,0) -> 0 | U47: =IF(D47="Mall",1,0) -> 0
... A72: STR-1018 | B72: 45717 | C72: East | D72: High Street | E72: 60571.82 | F72: 3193 | G72: 0.197 | H72: 99 | I72: =IF(C72="North",1,0) -> 0 | J72: 7 | K72: 99 | L72: 1.43 | M72: 0 | N72: 3.2 | O72: 605023.87 | P72: 98545.81 | Q72: =IF(C72="East",1,0) -> 1 | R72: =IF(C72="South",1,0) -> 0 | S72: =IF(D72="Airport",1,0) -> 0 | T72: =IF(D72="High Street",1,0) -> 1 | U72: =IF(D72="Mall",1,0) -> 0
A73: STR-1018 | B73: 45748 | C73: East | D73: High Street | E73: 55081.16 | F73: 5485 | G73: 0.036 | H73: 88 | I73: =IF(C73="North",1,0) -> 0 | J73: 12 | K73: 88 | M73: 0 | N73: 3.5 | O73: 674774.09 | P73: 141917.59 | Q73: =IF(C73="East",1,0) -> 1 | R73: =IF(C73="South",1,0) -> 0 | S73: =IF(D73="Airport",1,0) -> 0 | T73: =IF(D73="High Street",1,0) -> 1 | U73: =IF(D73="Mall",1,0) -> 0
A74: STR-1019 | B74: 45658 | C74: East | D74: Residential | E74: 46201.46 | F74: 5918 | G74: 0.277 | H74: 78.8 | I74: =IF(C74="North",1,0) -> 0 | J74: 13 | K74: 78.8 | L74: 4.91 | M74: 0 | N74: 4.5 | O74: 616069.41 | P74: 54453.99 | Q74: =IF(C74="East",1,0) -> 1 | R74: =IF(C74="South",1,0) -> 0 | S74: =IF(D74="Airport",1,0) -> 0 | T74: =IF(D74="High Street",1,0) -> 0 | U74: =IF(D74="Mall",1,0) -> 0
A75: STR-1019 | B75: 45689 | C75: East | D75: Residential | E75: 53762.92 | F75: 6821 | G75: 0.066 | H75: 94.6 | I75: =IF(C75="North",1,0) -> 0 | J75: 19 | K75: 94.6 | L75: 7.03 | M75: 0 | N75: 4.4 | O75: 630829.94 | P75: 117090.02 | Q75: =IF(C75="East",1,0) -> 1 | R75: =IF(C75="South",1,0) -> 0 | S75: =IF(D75="Airport",1,0) -> 0 | T75: =IF(D75="High Street",1,0) -> 0 | U75: =IF(D75="Mall",1,0) -> 0
A76: STR-1019 | B76: 45717 | C76: East | D76: Residential | E76: 70144.78 | F76: 6806 | G76: 0.178 | H76: 93.1 | I76: =IF(C76="North",1,0) -> 0 | J76: 20 | K76: 93.1 | L76: 0.28 | M76: 1 | N76: 4.3 | O76: 788087.68 | P76: 116803.42 | Q76: =IF(C76="East",1,0) -> 1 | R76: =IF(C76="South",1,0) -> 0 | S76: =IF(D76="Airport",1,0) -> 0 | T76: =IF(D76="High Street",1,0) -> 0 | U76: =IF(D76="Mall",1,0) -> 0
A77: STR-1019 | B77: 45748 | C77: East | D77: Residential | E77: 58749.63 | F77: 8252 | G77: 0.203 | H77: 85.2 | I77: =IF(C77="North",1,0) -> 0 | J77: 20 | K77: 85.2 | L77: 3.61 | M77: 0 | N77: 4.5 | O77: 680840.36 | P77: 68007.68 | Q77: =IF(C77="East",1,0) -> 1 | R77: =IF(C77="South",1,0) -> 0 | S77: =IF(D77="Airport",1,0) -> 0 | T77: =IF(D77="High Street",1,0) -> 0 | U77: =IF(D77="Mall",1,0) -> 0
A78: STR-1020 | B78: 45658 | C78: South | D78: High Street | E78: 56973.18 | F78: 6662 | G78: 0.1 | H78: 77.7 | I78: =IF(C78="North",1,0) -> 0 | J78: 15 | K78: 77.7 | L78: 7.52 | M78: 1 | N78: 3.2 | O78: 643657.47 | P78: 87022.45 | Q78: =IF(C78="East",1,0) -> 0 | R78: =IF(C78="South",1,0) -> 1 | S78: =IF(D78="Airport",1,0) -> 0 | T78: =IF(D78="High Street",1,0) -> 1 | U78: =IF(D78="Mall",1,0) -> 0
A79: STR-1020 | B79: 45689 | C79: South | D79: High Street | E79: 54872.82 | F79: 5962 | G79: 0.064 | H79: 85.4 | I79: =IF(C79="North",1,0) -> 0 | J79: 12 | K79: 85.4 | L79: 2.58 | M79: 0 | N79: 2.9 | O79: 691112.6 | P79: 109212.83 | Q79: =IF(C79="East",1,0) -> 0 | R79: =IF(C79="South",1,0) -> 1 | S79: =IF(D79="Airport",1,0) -> 0 | T79: =IF(D79="High Street",1,0) -> 1 | U79: =IF(D79="Mall",1,0) -> 0
A80: STR-1020 | B80: 45717 | C80: South | D80: High Street | E80: 80562.81 | F80: 7470 | G80: 0.172 | H80: 83.5 | I80: =IF(C80="North",1,0) -> 0 | J80: 16 | K80: 83.5 | L80: 2.29 | M80: 0 | N80: 3.3 | O80: 776922.17 | P80: 150701.93 | Q80: =IF(C80="East",1,0) -> 0 | R80: =IF(C80="South",1,0) -> 1 | S80: =IF(D80="Airport",1,0) -> 0 | T80: =IF(D80="High Street",1,0) -> 1 | U80: =IF(D80="Mall",1,0) -> 0
A81: STR-1020 | B81: 45748 | C81: South | D81: High Street | E81: 77999.9 | F81: 5974 | G81: 0.252 | H81: 81.3 | I81: =IF(C81="North",1,0) -> 0 | J81: 14 | K81: 81.3 | L81: 2.39 | M81: 0 | N81: 3.2 | O81: 636561.34 | P81: 93861.06 | Q81: =IF(C81="East",1,0) -> 0 | R81: =IF(C81="South",1,0) -> 1 | S81: =IF(D81="Airport",1,0) -> 0 | T81: =IF(D81="High Street",1,0) -> 1 | U81: =IF(D81="Mall",1,0) -> 0
A82: STR-1021 | B82: 45658 | C82: West | D82: Mall | E82: 60881.01 | F82: 5410 | G82: 0.179 | H82: 83.9 | I82: =IF(C82="North",1,0) -> 0 | J82: 15 | K82: 83.9 | L82: 5.24 | M82: 0 | N82: 4.6 | O82: 621369.58 | P82: 85493.64 | Q82: =IF(C82="East",1,0) -> 0 | R82: =IF(C82="South",1,0) -> 0 | S82: =IF(D82="Airport",1,0) -> 0 | T82: =IF(D82="High Street",1,0) -> 0 | U82: =IF(D82="Mall",1,0) -> 1
A83: STR-1021 | B83: 45689 | C83: West | D83: Mall | E83: 60628.38 | F83: 4451 | G83: 0.095 | H83: 89.6 | I83: =IF(C83="North",1,0) -> 0 | J83: 10 | K83: 89.6 | L83: 3.17 | M83: 0 | N83: 4.6 | O83: 682208.01 | P83: 110318.84 | Q83: =IF(C83="East",1,0) -> 0 | R83: =IF(C83="South",1,0) -> 0 | S83: =IF(D83="Airport",1,0) -> 0 | T83: =IF(D83="High Street",1,0) -> 0 | U83: =IF(D83="Mall",1,0) -> 1
A84: STR-1021 | B84: 45717 | C84: West | D84: Mall | E84: 72731.14 | F84: 4644 | G84: 0.084 | H84: 87.1 | I84: =IF(C84="North",1,0) -> 0 | J84: 15 | K84: 87.1 | L84: 2.66 | M84: 0 | N84: 4.6 | O84: 727241.86 | P84: 155810.3 | Q84: =IF(C84="East",1,0) -> 0 | R84: =IF(C84="South",1,0) -> 0 | S84: =IF(D84="Airport",1,0) -> 0 | T84: =IF(D84="High Street",1,0) -> 0 | U84: =IF(D84="Mall",1,0) -> 1
...

Sheet Simple_Regression_1
A1: SUMMARY OUTPUT
A3: Regression Statistics
A4: Multiple R | B4: 0.40895561
A5: R Square | B5: 0.16724469
A6: Adjusted R Square | B6: 0.16462596
A7: Standard Error | B7: 94846.034
A8: Observations | B8: 320
A10: ANOVA
B11: df | C11: SS | D11: MS | E11: F | F11: Significance F
A12: Regression | B12: 1 | C12: 5.7451371e+11 | D12: 5.7451371e+11 | E12: 63.864873 | F12: 2.4800615e-14
A13: Residual | B13: 318 | C13: 2.8606549e+12 | D13: 8.9957701e+09
A14: Total | B14: 319 | C14: 3.4351686e+12
B16: Coefficients | C16: Standard Error | D16: t Stat | E16: P-value | F16: Lower 95% | G16: Upper 95% | H16: Lower 95.0% | I16: Upper 95.0%
A17: Intercept | B17: 560777.35 | C17: 15906.906 | D17: 35.253703 | E17: 6.9528769e-112 | F17: 529481.27 | G17: 592073.42 | H17: 529481.27 | I17: 592073.42
A18: marketing_spend | B18: 2.1295753 | C18: 0.26647838 | D18: 7.9915501 | E18: 2.4800615e-14 | F18: 1.6052919 | G18: 2.6538587 | H18: 1.6052919 | I18: 2.6538587

Sheet Simple_Regression_2
A1: SUMMARY OUTPUT
A3: Regression Statistics
A4: Multiple R | B4: 0.85807071
A5: R Square | B5: 0.73628534
A6: Adjusted R Square | B6: 0.73545605
A7: Standard Error | B7: 53373.736
A8: Observations | B8: 320
A10: ANOVA
B11: df | C11: SS | D11: MS | E11: F | F11: Significance F
A12: Regression | B12: 1 | C12: 2.5292643e+12 | D12: 2.5292643e+12 | E12: 887.84878 | F12: 4.7503615e-94
A13: Residual | B13: 318 | C13: 9.0590432e+11 | D13: 2.8487557e+09
A14: Total | B14: 319 | C14: 3.4351686e+12
B16: Coefficients | C16: Standard Error | D16: t Stat | E16: P-value | F16: Lower 95% | G16: Upper 95% | H16: Lower 95.0% | I16: Upper 95.0%
A17: Intercept | B17: 446410.58 | C17: 8407.7383 | D17: 53.095205 | E17: 4.0862696e-160 | F17: 429868.76 | G17: 462952.4 | H17: 429868.76 | I17: 462952.4
A18: footfall | B18: 35.678031 | C18: 1.1973783 | D18: 29.796791 | E18: 4.7503615e-94 | F18: 33.322247 | G18: 38.033815 | H18: 33.322247 | I18: 38.033815

Sheet Multiple_Regression
A1: SUMMARY OUTPUT
A3: Regression Statistics
A4: Multiple R | B4: 0.89818306
A5: R Square | B5: 0.80673281
A6: Adjusted R Square | B6: 0.80365531
A7: Standard Error | B7: 45982.044
A8: Observations | B8: 320
A10: ANOVA
B11: df | C11: SS | D11: MS | E11: F | F11: Significance F
A12: Regression | B12: 5 | C12: 2.7712632e+12 | D12: 5.5425265e+11 | E12: 262.13875 | F12: 9.1893902e-110
A13: Residual | B13: 314 | C13: 6.6390539e+11 | D13: 2.1143484e+09
A14: Total | B14: 319 | C14: 3.4351686e+12
B16: Coefficients | C16: Standard Error | D16: t Stat | E16: P-value | F16: Lower 95% | G16: Upper 95% | H16: Lower 95.0% | I16: Upper 95.0%
A17: Intercept | B17: 151399.35 | C17: 44752.376 | D17: 3.3830461 | E17: 0.00080767051 | F17: 63346.917 | G17: 239451.78 | H17: 63346.917 | I17: 239451.78
A18: marketing_spend | B18: 1.1629255 | C18: 0.13324107 | D18: 8.7279814 | E18: 1.5563691e-16 | F18: 0.90076739 | G18: 1.4250837 | H18: 0.90076739 | I18: 1.4250837
A19: footfall | B19: 33.641173 | C19: 1.0643354 | D19: 31.60768 | E19: 1.445702e-99 | F19: 31.547042 | G19: 35.735304 | H19: 31.547042 | I19: 35.735304
A20: avg_discount_pct | B20: -70986.274 | C20: 38064.312 | D20: -1.8649036 | E20: 0.0631276 | F20: -145879.62 | G20: 3907.0755 | H20: -145879.62 | I20: 3907.0755
A21: inventory_availability_pct | B21: 2851.729 | C21: 482.99675 | D21: 5.9042406 | E21: 9.1916637e-09 | F21: 1901.4099 | G21: 3802.0482 | H21: 1901.4099 | I21: 3802.0482
A22: Region_North | B22: -217.03775 | C22: 6462.6781 | D22: -0.033583252 | E22: 0.97323082 | F22: -12932.665 | G22: 12498.59 | H22: -12932.665 | I22: 12498.59

Sheet Predictions_Residuals
A1: Actual Sales | B1: Predicted Sales | C1: Residual
A2: 685379.08 | B2: =151399.3501+(1.162925543*Dummy_Variables!E68)+(33.64117308*Dummy_Variables!F68)-(70986.27419*Dummy_Variables!G68)+(2851.729043*Dummy_Variables!H68)-(217.0377465*Dummy_Variables!I68) -> 842650.75 | C2: =A2-B2 -> -157271.67
A3: 595467.6 | B3: =151399.3501+(1.162925543*Dummy_Variables!E46)+(33.64117308*Dummy_Variables!F46)-(70986.27419*Dummy_Variables!G46)+(2851.729043*Dummy_Variables!H46)-(217.0377465*Dummy_Variables!I46) -> 733225.13 | C3: =A3-B3 -> -137757.53
A4: 627171.9 | B4: =151399.3501+(1.162925543*Dummy_Variables!E91)+(33.64117308*Dummy_Variables!F91)-(70986.27419*Dummy_Variables!G91)+(2851.729043*Dummy_Variables!H91)-(217.0377465*Dummy_Variables!I91) -> 744840.11 | C4: =A4-B4 -> -117668.21
A5: 641865.03 | B5: =151399.3501+(1.162925543*Dummy_Variables!E34)+(33.64117308*Dummy_Variables!F34)-(70986.27419*Dummy_Variables!G34)+(2851.729043*Dummy_Variables!H34)-(217.0377465*Dummy_Variables!I34) -> 756081.75 | C5: =A5-B5 -> -114216.72
A6: 658920.3 | B6: =151399.3501+(1.162925543*Dummy_Variables!E5)+(33.64117308*Dummy_Variables!F5)-(70986.27419*Dummy_Variables!G5)+(2851.729043*Dummy_Variables!H5)-(217.0377465*Dummy_Variables!I5) -> 772524.48 | C6: =A6-B6 -> -113604.18
A7: 538376 | B7: =151399.3501+(1.162925543*Dummy_Variables!E307)+(33.64117308*Dummy_Variables!F307)-(70986.27419*Dummy_Variables!G307)+(2851.729043*Dummy_Variables!H307)-(217.0377465*Dummy_Variables!I307) -> 644796.26 | C7: =A7-B7 -> -106420.26
A8: 463534.25 | B8: =151399.3501+(1.162925543*Dummy_Variables!E54)+(33.64117308*Dummy_Variables!F54)-(70986.27419*Dummy_Variables!G54)+(2851.729043*Dummy_Variables!H54)-(217.0377465*Dummy_Variables!I54) -> 557586.74 | C8: =A8-B8 -> -94052.492
A9: 415721.82 | B9: =151399.3501+(1.162925543*Dummy_Variables!E22)+(33.64117308*Dummy_Variables!F22)-(70986.27419*Dummy_Variables!G22)+(2851.729043*Dummy_Variables!H22)-(217.0377465*Dummy_Variables!I22) -> 506848.59 | C9: =A9-B9 -> -91126.77
A10: 678722.06 | B10: =151399.3501+(1.162925543*Dummy_Variables!E4)+(33.64117308*Dummy_Variables!F4)-(70986.27419*Dummy_Variables!G4)+(2851.729043*Dummy_Variables!H4)-(217.0377465*Dummy_Variables!I4) -> 769166.88 | C10: =A10-B10 -> -90444.815
A11: 800451.94 | B11: =151399.3501+(1.162925543*Dummy_Variables!E27)+(33.64117308*Dummy_Variables!F27)-(70986.27419*Dummy_Variables!G27)+(2851.729043*Dummy_Variables!H27)-(217.0377465*Dummy_Variables!I27) -> 888101.48 | C11: =A11-B11 -> -87649.54
A12: 511844.41 | B12: =151399.3501+(1.162925543*Dummy_Variables!E30)+(33.64117308*Dummy_Variables!F30)-(70986.27419*Dummy_Variables!G30)+(2851.729043*Dummy_Variables!H30)-(217.0377465*Dummy_Variables!I30) -> 598932.43 | C12: =A12-B12 -> -87088.022
A13: 633638.03 | B13: =151399.3501+(1.162925543*Dummy_Variables!E138)+(33.64117308*Dummy_Variables!F138)-(70986.27419*Dummy_Variables!G138)+(2851.729043*Dummy_Variables!H138)-(217.0377465*Dummy_Variables!I138) -> 719014.24 | C13: =A13-B13 -> -85376.208
A14: 593637.14 | B14: =151399.3501+(1.162925543*Dummy_Variables!E171)+(33.64117308*Dummy_Variables!F171)-(70986.27419*Dummy_Variables!G171)+(2851.729043*Dummy_Variables!H171)-(217.0377465*Dummy_Variables!I171) -> 677251.7 | C14: =A14-B14 -> -83614.564
A15: 449465.06 | B15: =151399.3501+(1.162925543*Dummy_Variables!E197)+(33.64117308*Dummy_Variables!F197)-(70986.27419*Dummy_Variables!G197)+(2851.729043*Dummy_Variables!H197)-(217.0377465*Dummy_Variables!I197) -> 532590.96 | C15: =A15-B15 -> -83125.905
A16: 634436 | B16: =151399.3501+(1.162925543*Dummy_Variables!E3)+(33.64117308*Dummy_Variables!F3)-(70986.27419*Dummy_Variables!G3)+(2851.729043*Dummy_Variables!H3)-(217.0377465*Dummy_Variables!I3) -> 716640.8 | C16: =A16-B16 -> -82204.796
A17: 427917.38 | B17: =151399.3501+(1.162925543*Dummy_Variables!E33)+(33.64117308*Dummy_Variables!F33)-(70986.27419*Dummy_Variables!G33)+(2851.729043*Dummy_Variables!H33)-(217.0377465*Dummy_Variables!I33) -> 509700.89 | C17: =A17-B17 -> -81783.513
A18: 691288.19 | B18: =151399.3501+(1.162925543*Dummy_Variables!E211)+(33.64117308*Dummy_Variables!F211)-(70986.27419*Dummy_Variables!G211)+(2851.729043*Dummy_Variables!H211)-(217.0377465*Dummy_Variables!I211) -> 772756.52 | C18: =A18-B18 -> -81468.332
A19: 660633.99 | B19: =151399.3501+(1.162925543*Dummy_Variables!E270)+(33.64117308*Dummy_Variables!F270)-(70986.27419*Dummy_Variables!G270)+(2851.729043*Dummy_Variables!H270)-(217.0377465*Dummy_Variables!I270) -> 742078.63 | C19: =A19-B19 -> -81444.643
A20: 593343 | B20: =151399.3501+(1.162925543*Dummy_Variables!E273)+(33.64117308*Dummy_Variables!F273)-(70986.27419*Dummy_Variables!G273)+(2851.729043*Dummy_Variables!H273)-(217.0377465*Dummy_Variables!I273) -> 673957.06 | C20: =A20-B20 -> -80614.061
A21: 675917.63 | B21: =151399.3501+(1.162925543*Dummy_Variables!E209)+(33.64117308*Dummy_Variables!F209)-(70986.27419*Dummy_Variables!G209)+(2851.729043*Dummy_Variables!H209)-(217.0377465*Dummy_Variables!I209) -> 755014.52 | C21: =A21-B21 -> -79096.895
A22: 673076.34 | B22: =151399.3501+(1.162925543*Dummy_Variables!E278)+(33.64117308*Dummy_Variables!F278)-(70986.27419*Dummy_Variables!G278)+(2851.729043*Dummy_Variables!H278)-(217.0377465*Dummy_Variables!I278) -> 751365.58 | C22: =A22-B22 -> -78289.239
A23: 630829.94 | B23: =151399.3501+(1.162925543*Dummy_Variables!E75)+(33.64117308*Dummy_Variables!F75)-(70986.27419*Dummy_Variables!G75)+(2851.729043*Dummy_Variables!H75)-(217.0377465*Dummy_Variables!I75) -> 708476.54 | C23: =A23-B23 -> -77646.598
A24: 401582.58 | B24: =151399.3501+(1.162925543*Dummy_Variables!E301)+(33.64117308*Dummy_Variables!F301)-(70986.27419*Dummy_Variables!G301)+(2851.729043*Dummy_Variables!H301)-(217.0377465*Dummy_Variables!I301) -> 475269.09 | C24: =A24-B24 -> -73686.506
A25: 684217.32 | B25: =151399.3501+(1.162925543*Dummy_Variables!E120)+(33.64117308*Dummy_Variables!F120)-(70986.27419*Dummy_Variables!G120)+(2851.729043*Dummy_Variables!H120)-(217.0377465*Dummy_Variables!I120) -> 753685.25 | C25: =A25-B25 -> -69467.926
A26: 799477.76 | B26: =151399.3501+(1.162925543*Dummy_Variables!E35)+(33.64117308*Dummy_Variables!F35)-(70986.27419*Dummy_Variables!G35)+(2851.729043*Dummy_Variables!H35)-(217.0377465*Dummy_Variables!I35) -> 866979.48 | C26: =A26-B26 -> -67501.721
A27: 725235.28 | B27: =151399.3501+(1.162925543*Dummy_Variables!E132)+(33.64117308*Dummy_Variables!F132)-(70986.27419*Dummy_Variables!G132)+(2851.729043*Dummy_Variables!H132)-(217.0377465*Dummy_Variables!I132) -> 791265.71 | C27: =A27-B27 -> -66030.435
A28: 658832.62 | B28: =151399.3501+(1.162925543*Dummy_Variables!E2)+(33.64117308*Dummy_Variables!F2)-(70986.27419*Dummy_Variables!G2)+(2851.729043*Dummy_Variables!H2)-(217.0377465*Dummy_Variables!I2) -> 723443.92 | C28: =A28-B28 -> -64611.298
A29: 570963.31 | B29: =151399.3501+(1.162925543*Dummy_Variables!E230)+(33.64117308*Dummy_Variables!F230)-(70986.27419*Dummy_Variables!G230)+(2851.729043*Dummy_Variables!H230)-(217.0377465*Dummy_Variables!I230) -> 635128.62 | C29: =A29-B29 -> -64165.308
A30: 721079.35 | B30: =151399.3501+(1.162925543*Dummy_Variables!E238)+(33.64117308*Dummy_Variables!F238)-(70986.27419*Dummy_Variables!G238)+(2851.729043*Dummy_Variables!H238)-(217.0377465*Dummy_Variables!I238) -> 785142.02 | C30: =A30-B30 -> -64062.669
A31: 651164.18 | B31: =151399.3501+(1.162925543*Dummy_Variables!E309)+(33.64117308*Dummy_Variables!F309)-(70986.27419*Dummy_Variables!G309)+(2851.729043*Dummy_Variables!H309)-(217.0377465*Dummy_Variables!I309) -> 714237.45 | C31: =A31-B31 -> -63073.273
A32: 671868.59 | B32: =151399.3501+(1.162925543*Dummy_Variables!E208)+(33.64117308*Dummy_Variables!F208)-(70986.27419*Dummy_Variables!G208)+(2851.729043*Dummy_Variables!H208)-(217.0377465*Dummy_Variables!I208) -> 734549.07 | C32: =A32-B32 -> -62680.479
A33: 620264.2 | B33: =151399.3501+(1.162925543*Dummy_Variables!E318)+(33.64117308*Dummy_Variables!F318)-(70986.27419*Dummy_Variables!G318)+(2851.729043*Dummy_Variables!H318)-(217.0377465*Dummy_Variables!I318) -> 682772.69 | C33: =A33-B33 -> -62508.491
A34: 441275.42 | B34: =151399.3501+(1.162925543*Dummy_Variables!E125)+(33.64117308*Dummy_Variables!F125)-(70986.27419*Dummy_Variables!G125)+(2851.729043*Dummy_Variables!H125)-(217.0377465*Dummy_Variables!I125) -> 501037.86 | C34: =A34-B34 -> -59762.441
A35: 726606.28 | B35: =151399.3501+(1.162925543*Dummy_Variables!E15)+(33.64117308*Dummy_Variables!F15)-(70986.27419*Dummy_Variables!G15)+(2851.729043*Dummy_Variables!H15)-(217.0377465*Dummy_Variables!I15) -> 786170.02 | C35: =A35-B35 -> -59563.737
A36: 400831.65 | B36: =151399.3501+(1.162925543*Dummy_Variables!E135)+(33.64117308*Dummy_Variables!F135)-(70986.27419*Dummy_Variables!G135)+(2851.729043*Dummy_Variables!H135)-(217.0377465*Dummy_Variables!I135) -> 455236.99 | C36: =A36-B36 -> -54405.34
A37: 527300.13 | B37: =151399.3501+(1.162925543*Dummy_Variables!E134)+(33.64117308*Dummy_Variables!F134)-(70986.27419*Dummy_Variables!G134)+(2851.729043*Dummy_Variables!H134)-(217.0377465*Dummy_Variables!I134) -> 580337.55 | C37: =A37-B37 -> -53037.42
A38: 509484.81 | B38: =151399.3501+(1.162925543*Dummy_Variables!E122)+(33.64117308*Dummy_Variables!F122)-(70986.27419*Dummy_Variables!G122)+(2851.729043*Dummy_Variables!H122)-(217.0377465*Dummy_Variables!I122) -> 562296.4 | C38: =A38-B38 -> -52811.591
A39: 553756.43 | B39: =151399.3501+(1.162925543*Dummy_Variables!E61)+(33.64117308*Dummy_Variables!F61)-(70986.27419*Dummy_Variables!G61)+(2851.729043*Dummy_Variables!H61)-(217.0377465*Dummy_Variables!I61) -> 606358.59 | C39: =A39-B39 -> -52602.164
A40: 643428.85 | B40: =151399.3501+(1.162925543*Dummy_Variables!E194)+(33.64117308*Dummy_Variables!F194)-(70986.27419*Dummy_Variables!G194)+(2851.729043*Dummy_Variables!H194)-(217.0377465*Dummy_Variables!I194) -> 693349.63 | C40: =A40-B40 -> -49920.778
...

Sheet Model_Comparison
A1: Model | B1: Dependent Variable | C1: Independent Variables | D1: R² | E1: Significant Variables | F1: Business Usefulness
A2: Simple Model 1 | B2: Monthly Sales | C2: Marketing Spend | D2: 0.167 | E2: Marketing Spend | F2: Weak to Moderate
A3: Simple Model 2 | B3: Monthly Sales | C3: Footfall | D3: 0.736 | E3: Footfall | F3: Strong
A4: Multiple Regression | B4: Monthly Sales | C4: Marketing Spend, Footfall, Avg Discount Pct, Inventory Availability Pct, Region_North | D4: 0.807 | E4: Marketing Spend, Footfall, Inventory Availability Pct | F4: Very Strong
